Workbook

Sheet Datenquelle
A1: Country | B1: League | C1: Season | D1: Date | E1: Time | F1: Home | G1: Away | H1: HG | I1: AG | J1: Res | K1: PSCH | L1: PSCD | M1: PSCA | N1: MaxCH | O1: MaxCD | P1: MaxCA | Q1: AvgCH | R1: AvgCD | S1: AvgCA | T1: BFECH | U1: BFECD | V1: BFECA | W1: B365CH | X1: B365CD | Y1: B365CA
A2: Austria | B2: Bundesliga | C2: 2012/2013 | D2: 41111 | E2: 0.625 | F2: Sturm Graz | G2: Salzburg | H2: 0 | I2: 2 | J2: A | K2: 326 | L2: 334 | M2: 24 | N2: 326 | O2: 34 | P2: 25 | Q2: 296 | R2: 32 | S2: 233
A3: Austria | B3: Bundesliga | C3: 2012/2013 | D3: 41111 | E3: 0.72916667 | F3: Mattersburg | G3: Neustadt | H3: 2 | I3: 0 | J3: H | K3: 179 | L3: 381 | M3: 5 | N3: 19 | O3: 381 | P3: 5 | Q3: 177 | R3: 351 | S3: 433
A4: Austria | B4: Bundesliga | C4: 2012/2013 | D4: 41111 | E4: 0.72916667 | F4: SK Rapid | G4: Wacker Innsbruck | H4: 4 | I4: 0 | J4: H | K4: 15 | L4: 446 | M4: 772 | N4: 15 | O4: 446 | P4: 809 | Q4: 145 | R4: 409 | S4: 709
A5: Austria | B5: Bundesliga | C5: 2012/2013 | D5: 41112 | E5: 0.625 | F5: Admira | G5: Ried | H5: 0 | I5: 2 | J5: A | K5: 218 | L5: 351 | M5: 361 | N5: 218 | O5: 351 | P5: 377 | Q5: 212 | R5: 329 | S5: 332
A6: Austria | B6: Bundesliga | C6: 2012/2013 | D6: 41115 | E6: 0.72916667 | F6: Wolfsberger AC | G6: Austria Vienna | H6: 0 | I6: 1 | J6: A | K6: 383 | L6: 362 | M6: 206 | N6: 383 | O6: 362 | P6: 21 | Q6: 353 | R6: 328 | S6: 2
A7: Austria | B7: Bundesliga | C7: 2012/2013 | D7: 41118 | E7: 0.72916667 | F7: Austria Vienna | G7: Sturm Graz | H7: 0 | I7: 1 | J7: A | K7: 212 | L7: 342 | M7: 391 | N7: 215 | O7: 36 | P7: 403 | Q7: 199 | R7: 329 | S7: 367
A8: Austria | B8: Bundesliga | C8: 2012/2013 | D8: 41118 | E8: 0.72916667 | F8: Neustadt | G8: SK Rapid | H8: 0 | I8: 1 | J8: A | K8: 638 | L8: 413 | M8: 161 | N8: 675 | O8: 413 | P8: 17 | Q8: 58 | R8: 371 | S8: 157
A9: Austria | B9: Bundesliga | C9: 2012/2013 | D9: 41118 | E9: 0.72916667 | F9: Salzburg | G9: Mattersburg | H9: 3 | I9: 2 | J9: H | K9: 14 | L9: 484 | M9: 951 | N9: 14 | O9: 505 | P9: 10 | Q9: 136 | R9: 452 | S9: 839
A10: Austria | B10: Bundesliga | C10: 2012/2013 | D10: 41119 | E10: 0.625 | F10: Wacker Innsbruck | G10: Admira | H10: 1 | I10: 2 | J10: A | K10: 244 | L10: 352 | M10: 308 | N10: 244 | O10: 353 | P10: 335 | Q10: 222 | R10: 327 | S10: 309
A11: Austria | B11: Bundesliga | C11: 2012/2013 | D11: 41119 | E11: 0.72916667 | F11: Ried | G11: Wolfsberger AC | H11: 0 | I11: 2 | J11: A | K11: 151 | L11: 437 | M11: 778 | N11: 175 | O11: 437 | P11: 778 | Q11: 153 | R11: 38 | S11: 616
A12: Austria | B12: Bundesliga | C12: 2012/2013 | D12: 41125 | E12: 0.72916667 | F12: Wolfsberger AC | G12: Salzburg | H12: 0 | I12: 2 | J12: A | K12: 578 | L12: 382 | M12: 171 | N12: 578 | O12: 382 | P12: 175 | Q12: 492 | R12: 363 | S12: 166
A13: Austria | B13: Bundesliga | C13: 2012/2013 | D13: 41125 | E13: 0.72916667 | F13: Mattersburg | G13: Sturm Graz | H13: 3 | I13: 1 | J13: H | K13: 264 | L13: 327 | M13: 296 | N13: 267 | O13: 332 | P13: 303 | Q13: 252 | R13: 318 | S13: 271
... A329: Austria | B329: Bundesliga | C329: 2013/2014 | D329: 41727 | E329: 0.75 | F329: Admira | G329: Grodig | H329: 4 | I329: 0 | J329: H | K329: 229 | L329: 368 | M329: 315 | N329: 23 | O329: 375 | P329: 34 | Q329: 216 | R329: 338 | S329: 32
A330: Austria | B330: Bundesliga | C330: 2013/2014 | D330: 41727 | E330: 0.75 | F330: Salzburg | G330: Wacker Innsbruck | H330: 0 | I330: 0 | J330: D | N330: 115 | O330: 14 | P330: 41 | Q330: 108 | R330: 1028 | S330: 2157
A331: Austria | B331: Bundesliga | C331: 2013/2014 | D331: 41728 | E331: 0.64583333 | F331: Ried | G331: Austria Vienna | H331: 2 | I331: 2 | J331: D | K331: 365 | L331: 352 | M331: 214 | N331: 405 | O331: 365 | P331: 22 | Q331: 354 | R331: 336 | S331: 204
A332: Austria | B332: Bundesliga | C332: 2013/2014 | D332: 41734 | E332: 0.64583333 | F332: Grodig | G332: Salzburg | H332: 1 | I332: 3 | J332: A | K332: 1017 | L332: 632 | M332: 13 | N332: 1017 | O332: 632 | P332: 15 | Q332: 842 | R332: 528 | S332: 132
A333: Austria | B333: Bundesliga | C333: 2013/2014 | D333: 41734 | E333: 0.75 | F333: Neustadt | G333: Ried | H333: 1 | I333: 1 | J333: D | K333: 265 | L333: 341 | M333: 283 | N333: 31 | O333: 342 | P333: 285 | Q333: 264 | R333: 33 | S333: 258
A334: Austria | B334: Bundesliga | C334: 2013/2014 | D334: 41734 | E334: 0.75 | F334: Sturm Graz | G334: Admira | H334: 1 | I334: 1 | J334: D | K334: 199 | L334: 364 | M334: 404 | N334: 218 | O334: 364 | P334: 404 | Q334: 204 | R334: 336 | S334: 355
A335: Austria | B335: Bundesliga | C335: 2013/2014 | D335: 41734 | E335: 0.75 | F335: Wacker Innsbruck | G335: Wolfsberger AC | H335: 0 | I335: 1 | J335: A | K335: 253 | L335: 348 | M335: 292 | N335: 255 | O335: 35 | P335: 295 | Q335: 243 | R335: 328 | S335: 282
A336: Austria | B336: Bundesliga | C336: 2013/2014 | D336: 41735 | E336: 0.58333333 | F336: Austria Vienna | G336: SK Rapid | H336: 0 | I336: 1 | J336: A | K336: 264 | L336: 326 | M336: 294 | N336: 267 | O336: 355 | P336: 32 | Q336: 247 | R336: 317 | S336: 286
A337: Austria | B337: Bundesliga | C337: 2013/2014 | D337: 41741 | E337: 0.64583333 | F337: Salzburg | G337: Sturm Graz | H337: 1 | I337: 2 | J337: A | K337: 125 | L337: 676 | M337: 1297 | N337: 125 | O337: 7 | P337: 14 | Q337: 121 | R337: 621 | S337: 1198
A338: Austria | B338: Bundesliga | C338: 2013/2014 | D338: 41741 | E338: 0.75 | F338: Wolfsberger AC | G338: Grodig | H338: 1 | I338: 2 | J338: A | K338: 204 | L338: 366 | M338: 382 | N338: 22 | O338: 366 | P338: 382 | Q338: 206 | R338: 345 | S338: 338
A339: Austria | B339: Bundesliga | C339: 2013/2014 | D339: 41741 | E339: 0.75 | F339: SK Rapid | G339: Admira | H339: 0 | I339: 0 | J339: D | K339: 162 | L339: 412 | M339: 603 | N339: 164 | O339: 425 | P339: 64 | Q339: 16 | R339: 388 | S339: 534
A340: Austria | B340: Bundesliga | C340: 2013/2014 | D340: 41741 | E340: 0.75 | F340: Ried | G340: Wacker Innsbruck | H340: 1 | I340: 2 | J340: A | K340: 186 | L340: 377 | M340: 451 | N340: 195 | O340: 385 | P340: 46 | Q340: 18 | R340: 363 | S340: 416
A341: Austria | B341: Bundesliga | C341: 2013/2014 | D341: 41742 | E341: 0.64583333 | F341: Neustadt | G341: Austria Vienna | H341: 0 | I341: 2 | J341: A | K341: 474 | L341: 38 | M341: 181 | N341: 53 | O341: 42 | P341: 186 | Q341: 432 | R341: 364 | S341: 177
A342: Austria | B342: Bundesliga | C342: 2013/2014 | D342: 41748 | E342: 0.64583333 | F342: Austria Vienna | G342: Wolfsberger AC | H342: 3 | I342: 1 | J342: H | K342: 145 | L342: 489 | M342: 778 | N342: 151 | O342: 49 | P342: 778 | Q342: 145 | R342: 435 | S342: 671
... A415: Austria | B415: Bundesliga | C415: 2014/2015 | D415: 41917 | E415: 0.64583333 | F415: Ried | G415: SK Rapid | H415: 1 | I415: 2 | J415: A | K415: 388 | L415: 362 | M415: 204 | N415: 39 | O415: 375 | P415: 215 | Q415: 344 | R415: 344 | S415: 204
A416: Austria | B416: Bundesliga | C416: 2014/2015 | D416: 41917 | E416: 0.75 | F416: Salzburg | G416: Neustadt | H416: 4 | I416: 1 | J416: H | N416: 108 | O416: 17 | P416: 43 | Q416: 106 | R416: 118 | S416: 2271
A417: Austria | B417: Bundesliga | C417: 2014/2015 | D417: 41930 | E417: 0.625 | F417: Salzburg | G417: Ried | H417: 4 | I417: 2 | J417: H | K417: 113 | L417: 1092 | M417: 18 | N417: 114 | O417: 12 | P417: 26 | Q417: 111 | R417: 881 | S417: 1702
A418: Austria | B418: Bundesliga | C418: 2014/2015 | D418: 41930 | E418: 0.72916667 | F418: Wolfsberger AC | G418: Grodig | H418: 1 | I418: 2 | J418: A | K418: 188 | L418: 387 | M418: 427 | N418: 191 | O418: 395 | P418: 5 | Q418: 181 | R418: 362 | S418: 411
A419: Austria | B419: Bundesliga | C419: 2014/2015 | D419: 41930 | E419: 0.72916667 | F419: Altach | G419: Austria Vienna | H419: 1 | I419: 1 | J419: D | K419: 32 | L419: 351 | M419: 233 | N419: 32 | O419: 355 | P419: 245 | Q419: 296 | R419: 331 | S419: 231
A420: Austria | B420: Bundesliga | C420: 2014/2015 | D420: 41930 | E420: 0.72916667 | F420: SK Rapid | G420: Admira | H420: 0 | I420: 0 | J420: D | K420: 152 | L420: 451 | M420: 681 | N420: 152 | O420: 485 | P420: 77 | Q420: 147 | R420: 424 | S420: 65
A421: Austria | B421: Bundesliga | C421: 2014/2015 | D421: 41931 | E421: 0.64583333 | F421: Neustadt | G421: Sturm Graz | H421: 0 | I421: 0 | J421: D | K421: 367 | L421: 363 | M421: 209 | N421: 395 | O421: 375 | P421: 211 | Q421: 353 | R421: 348 | S421: 2
A422: Austria | B422: Bundesliga | C422: 2014/2015 | D422: 41937 | E422: 0.625 | F422: Sturm Graz | G422: SK Rapid | H422: 1 | I422: 3 | J422: A | K422: 316 | L422: 334 | M422: 244 | N422: 316 | O422: 34 | P422: 26 | Q422: 288 | R422: 32 | S422: 242
A423: Austria | B423: Bundesliga | C423: 2014/2015 | D423: 41937 | E423: 0.72916667 | F423: Wolfsberger AC | G423: Altach | H423: 0 | I423: 0 | J423: D | K423: 191 | L423: 377 | M423: 423 | N423: 2 | O423: 377 | P423: 425 | Q423: 189 | R423: 351 | S423: 388
A424: Austria | B424: Bundesliga | C424: 2014/2015 | D424: 41937 | E424: 0.72916667 | F424: Admira | G424: Ried | H424: 0 | I424: 0 | J424: D | K424: 248 | L424: 343 | M424: 304 | N424: 248 | O424: 36 | P424: 32 | Q424: 229 | R424: 333 | S424: 299
A425: Austria | B425: Bundesliga | C425: 2014/2015 | D425: 41937 | E425: 0.72916667 | F425: Austria Vienna | G425: Neustadt | H425: 2 | I425: 0 | J425: H | K425: 139 | L425: 542 | M425: 841 | N425: 14 | O425: 56 | P425: 94 | Q425: 136 | R425: 494 | S425: 741
A426: Austria | B426: Bundesliga | C426: 2014/2015 | D426: 41938 | E426: 0.64583333 | F426: Grodig | G426: Salzburg | H426: 2 | I426: 2 | J426: D | K426: 87 | L426: 582 | M426: 135 | N426: 10 | O426: 64 | P426: 137 | Q426: 769 | R426: 533 | S426: 133
A427: Austria | B427: Bundesliga | C427: 2014/2015 | D427: 41944 | E427: 0.625 | F427: Austria Vienna | G427: Sturm Graz | H427: 0 | I427: 3 | J427: A | K427: 198 | L427: 356 | M427: 417 | N427: 204 | O427: 37 | P427: 45 | Q427: 189 | R427: 342 | S427: 405
...

Sheet AT2526
A1: Country | B1: League | C1: Season | D1: Date | E1: Time | F1: Home | G1: Away | H1: HG | I1: AG | J1: Res | K1: PSCH | L1: PSCD | M1: PSCA | N1: MaxCH | O1: MaxCD | P1: MaxCA | Q1: AvgCH | R1: AvgCD | S1: AvgCA | T1: BFECH | U1: BFECD | V1: BFECA | W1: B365CH | X1: B365CD | Y1: B365CA
A2: Austria | B2: Bundesliga | C2: 2025/2026 | D2: 45870 | E2: 0.8125 | F2: LASK | G2: Sturm Graz | H2: 0 | I2: 2 | J2: A | K2: 236 | L2: 361 | M2: 3 | N2: 25 | O2: 361 | P2: 3 | Q2: 237 | R2: 344 | S2: 271 | T2: 2.58 | U2: 3.65 | V2: 2.9
A3: Austria | B3: Bundesliga | C3: 2025/2026 | D3: 45871 | E3: 0.66666667 | F3: Tirol | G3: Hartberg | H3: 4 | I3: 2 | J3: H | K3: 271 | L3: 33 | M3: 278 | N3: 271 | O3: 35 | P3: 325 | Q3: 224 | R3: 326 | S3: 307 | T3: 2.24 | U3: 3.4 | V3: 3.7
A4: Austria | B4: Bundesliga | C4: 2025/2026 | D4: 45871 | E4: 0.66666667 | F4: Wolfsberger AC | G4: Altach | H4: 0 | I4: 2 | J4: A | K4: 191 | L4: 377 | M4: 407 | N4: 215 | O4: 377 | P4: 407 | Q4: 206 | R4: 334 | S4: 337 | T4: 2.22 | U4: 3.5 | V4: 3.6
A5: Austria | B5: Bundesliga | C5: 2025/2026 | D5: 45871 | E5: 0.77083333 | F5: Ried | G5: Salzburg | H5: 2 | I5: 2 | J5: D | K5: 51 | L5: 418 | M5: 166 | N5: 525 | O5: 418 | P5: 17 | Q5: 495 | R5: 372 | S5: 164 | T5: 6 | U5: 4.4 | V5: 1.63
A6: Austria | B6: Bundesliga | C6: 2025/2026 | D6: 45872 | E6: 0.66666667 | F6: Grazer AK | G6: Austria Vienna | H6: 2 | I6: 2 | J6: D | K6: 376 | L6: 373 | M6: 2 | N6: 45 | O6: 39 | P6: 2 | Q6: 397 | R6: 362 | S6: 18 | T6: 4.1 | U6: 3.95 | V6: 1.95
A7: Austria | B7: Bundesliga | C7: 2025/2026 | D7: 45872 | E7: 0.66666667 | F7: SK Rapid | G7: BW Linz | H7: 1 | I7: 0 | J7: H | K7: 193 | L7: 354 | M7: 381 | N7: 193 | O7: 39 | P7: 433 | Q7: 181 | R7: 36 | S7: 401 | T7: 1.9 | U7: 3.9 | V7: 4.6
A8: Austria | B8: Bundesliga | C8: 2025/2026 | D8: 45878 | E8: 0.66666667 | F8: Altach | G8: Ried | H8: 1 | I8: 0 | J8: H | K8: 226 | L8: 286 | M8: 412 | N8: 238 | O8: 3 | P8: 4 | Q8: 216 | R8: 284 | S8: 374 | T8: 2.32 | U8: 3.05 | V8: 4
A9: Austria | B9: Bundesliga | C9: 2025/2026 | D9: 45878 | E9: 0.66666667 | F9: BW Linz | G9: Hartberg | H9: 0 | I9: 1 | J9: A | K9: 205 | L9: 348 | M9: 387 | N9: 184 | O9: 4 | P9: 55 | Q9: 17 | R9: 364 | S9: 463 | T9: 1.77 | U9: 3.85 | V9: 5.5
A10: Austria | B10: Bundesliga | C10: 2025/2026 | D10: 45878 | E10: 0.77083333 | F10: Salzburg | G10: Grazer AK | H10: 5 | I10: 0 | J10: H | K10: 135 | L10: 52 | M10: 964 | N10: 144 | O10: 5 | P10: 8 | Q10: 14 | R10: 467 | S10: 667 | T10: 1.45 | U10: 5 | V10: 8.2
A11: Austria | B11: Bundesliga | C11: 2025/2026 | D11: 45879 | E11: 0.66666667 | F11: Austria Vienna | G11: Wolfsberger AC | H11: 0 | I11: 2 | J11: A | K11: 2 | L11: 365 | M11: 385 | N11: 21 | O11: 38 | P11: 35 | Q11: 199 | R11: 353 | S11: 336 | T11: 2.1 | U11: 3.8 | V11: 3.7
A12: Austria | B12: Bundesliga | C12: 2025/2026 | D12: 45879 | E12: 0.66666667 | F12: Sturm Graz | G12: SK Rapid | H12: 1 | I12: 2 | J12: A | K12: 216 | L12: 363 | M12: 338 | N12: 225 | O12: 375 | P12: 32 | Q12: 213 | R12: 349 | S12: 309 | T12: 2.22 | U12: 3.6 | V12: 3.5
A13: Austria | B13: Bundesliga | C13: 2025/2026 | D13: 45879 | E13: 0.66666667 | F13: Tirol | G13: LASK | H13: 3 | I13: 1 | J13: H | K13: 348 | L13: 358 | M13: 214 | N13: 36 | O13: 375 | P13: 212 | Q13: 333 | R13: 355 | S13: 201 | T13: 3.6 | U13: 3.8 | V13: 2.14
A14: Austria | B14: Bundesliga | C14: 2025/2026 | D14: 45885 | E14: 0.66666667 | F14: Grazer AK | G14: Tirol | H14: 1 | I14: 1 | J14: D | K14: 225 | L14: 379 | M14: 307 | N14: 27 | O14: 36 | P14: 27 | Q14: 258 | R14: 339 | S14: 252 | T14: 2.72 | U14: 3.85 | V14: 2.68 | W14: 2.63 | X14: 3.5 | Y14: 2.5
A15: Austria | B15: Bundesliga | C15: 2025/2026 | D15: 45885 | E15: 0.66666667 | F15: Hartberg | G15: Salzburg | H15: 1 | I15: 2 | J15: A | K15: 675 | L15: 464 | M15: 148 | N15: 75 | O15: 48 | P15: 145 | Q15: 658 | R15: 458 | S15: 141 | T15: 7.8 | U15: 5.1 | V15: 1.45 | W15: 6.5 | X15: 4.75 | Y15: 1.42
A16: Austria | B16: Bundesliga | C16: 2025/2026 | D16: 45885 | E16: 0.77083333 | F16: Ried | G16: Sturm Graz | H16: 1 | I16: 3 | J16: A | K16: 437 | L16: 385 | M16: 183 | N16: 42 | O16: 39 | P16: 185 | Q16: 397 | R16: 376 | S16: 178 | T16: 4.4 | U16: 4 | V16: 1.85 | W16: 4.2 | X16: 3.9 | Y16: 1.75
A17: Austria | B17: Bundesliga | C17: 2025/2026 | D17: 45886 | E17: 0.66666667 | F17: LASK | G17: Austria Vienna | H17: 2 | I17: 1 | J17: H | K17: 262 | L17: 378 | M17: 259 | N17: 255 | O17: 37 | P17: 26 | Q17: 25 | R17: 352 | S17: 252 | T17: 2.66 | U17: 3.85 | V17: 2.68 | W17: 2.5 | X17: 3.7 | Y17: 2.55
A18: Austria | B18: Bundesliga | C18: 2025/2026 | D18: 45886 | E18: 0.66666667 | F18: SK Rapid | G18: Altach | H18: 0 | I18: 0 | J18: D | K18: 198 | L18: 367 | M18: 387 | N18: 19 | O18: 375 | P18: 45 | Q18: 18 | R18: 357 | S18: 408 | T18: 1.85 | U18: 3.9 | V18: 4.8 | W18: 1.75 | X18: 3.7 | Y18: 4.33
A19: Austria | B19: Bundesliga | C19: 2025/2026 | D19: 45886 | E19: 0.66666667 | F19: Wolfsberger AC | G19: BW Linz | H19: 3 | I19: 0 | J19: H | K19: 196 | L19: 365 | M19: 399 | N19: 199 | O19: 365 | P19: 4 | Q19: 192 | R19: 345 | S19: 371 | T19: 2 | U19: 3.7 | V19: 4.1 | W19: 1.91 | X19: 3.6 | Y19: 3.9
A20: Austria | B20: Bundesliga | C20: 2025/2026 | D20: 45892 | E20: 0.66666667 | F20: BW Linz | G20: Ried | H20: 0 | I20: 2 | J20: A | K20: 228 | L20: 329 | M20: 344 | N20: 263 | O20: 34 | P20: 32 | Q20: 246 | R20: 316 | S20: 281 | T20: 2.64 | U20: 3.3 | V20: 3 | W20: 2.63 | X20: 3.25 | Y20: 2.75
A21: Austria | B21: Bundesliga | C21: 2025/2026 | D21: 45892 | E21: 0.66666667 | F21: Salzburg | G21: LASK | H21: 3 | I21: 0 | J21: H | K21: 162 | L21: 442 | M21: 515 | N21: 161 | O21: 44 | P21: 525 | Q21: 157 | R21: 419 | S21: 488 | T21: 1.65 | U21: 4.5 | V21: 5.6 | W21: 1.6 | X21: 4 | Y21: 5.25
A22: Austria | B22: Bundesliga | C22: 2025/2026 | D22: 45893 | E22: 0.66666667 | F22: Altach | G22: Grazer AK | H22: 1 | I22: 1 | J22: D | K22: 2 | L22: 344 | M22: 41 | N22: 198 | O22: 35 | P22: 46 | Q22: 185 | R22: 337 | S22: 413 | T22: 1.91 | U22: 3.5 | V22: 5 | W22: 1.8 | X22: 3.5 | Y22: 4.33
A23: Austria | B23: Bundesliga | C23: 2025/2026 | D23: 45893 | E23: 0.66666667 | F23: Austria Vienna | G23: Hartberg | H23: 1 | I23: 3 | J23: A | K23: 169 | L23: 417 | M23: 483 | N23: 166 | O23: 41 | P23: 525 | Q23: 163 | R23: 388 | S23: 483 | T23: 1.68 | U23: 4.1 | V23: 5.6 | W23: 1.65 | X23: 4 | Y23: 5
A24: Austria | B24: Bundesliga | C24: 2025/2026 | D24: 45893 | E24: 0.66666667 | F24: Wolfsberger AC | G24: SK Rapid | H24: 1 | I24: 2 | J24: A | K24: 261 | L24: 356 | M24: 271 | N24: 27 | O24: 36 | P24: 265 | Q24: 256 | R24: 342 | S24: 252 | T24: 2.78 | U24: 3.55 | V24: 2.68 | W24: 2.63 | X24: 3.5 | Y24: 2.5
A25: Austria | B25: Bundesliga | C25: 2025/2026 | D25: 45899 | E25: 0.66666667 | F25: LASK | G25: Ried | H25: 1 | I25: 3 | J25: A | K25: 2 | L25: 361 | M25: 387 | N25: 21 | O25: 365 | P25: 37 | Q25: 199 | R25: 348 | S25: 344 | T25: 2.06 | U25: 3.65 | V25: 3.85 | W25: 2.1 | X25: 3.25 | Y25: 3.7
... A66: Austria | B66: Bundesliga | C66: 2025/2026 | D66: 45956 | E66: 0.66666667 | F66: Austria Vienna | G66: Salzburg | H66: 0 | I66: 3 | J66: A | K66: 313 | L66: 371 | M66: 217 | N66: 285 | O66: 36 | P66: 245 | Q66: 269 | R66: 35 | S66: 235 | T66: 2.84 | U66: 3.75 | V66: 2.56 | W66: 2.7 | X66: 3.4 | Y66: 2.35
A67: Austria | B67: Bundesliga | C67: 2025/2026 | D67: 45962 | E67: 0.66666667 | F67: BW Linz | G67: LASK | H67: 0 | I67: 1 | J67: A | N67: 37 | O67: 35 | P67: 21 | Q67: 343 | R67: 334 | S67: 204 | T67: 4 | U67: 3.55 | V67: 2.08 | W67: 3.5 | X67: 3.5 | Y67: 2.01
A68: Austria | B68: Bundesliga | C68: 2025/2026 | D68: 45962 | E68: 0.66666667 | F68: Grazer AK | G68: Altach | H68: 3 | I68: 1 | J68: H | N68: 35 | O68: 325 | P68: 225 | Q68: 336 | R68: 298 | S68: 222 | T68: 3.7 | U68: 3.1 | V68: 2.4 | W68: 3.3 | X68: 3.25 | Y68: 2.15
A69: Austria | B69: Bundesliga | C69: 2025/2026 | D69: 45962 | E69: 0.66666667 | F69: Hartberg | G69: Austria Vienna | H69: 2 | I69: 1 | J69: H | N69: 39 | O69: 35 | P69: 205 | Q69: 356 | R69: 337 | S69: 197 | T69: 4 | U69: 3.6 | V69: 2.06 | W69: 3.9 | X69: 3.4 | Y69: 1.91
A70: Austria | B70: Bundesliga | C70: 2025/2026 | D70: 45963 | E70: 0.5625 | F70: Salzburg | G70: Ried | H70: 4 | I70: 1 | J70: H | N70: 2 | O70: 38 | P70: 4 | Q70: 192 | R70: 355 | S70: 354 | T70: 2.02 | U70: 3.75 | V70: 4 | W70: 1.96 | X70: 3.8 | Y70: 3.3
A71: Austria | B71: Bundesliga | C71: 2025/2026 | D71: 45963 | E71: 0.5625 | F71: Wolfsberger AC | G71: Tirol | H71: 0 | I71: 0 | J71: D | N71: 17 | O71: 395 | P71: 533 | Q71: 164 | R71: 372 | S71: 482 | T71: 1.74 | U71: 3.9 | V71: 5.4 | W71: 1.62 | X71: 3.8 | Y71: 4.75
A72: Austria | B72: Bundesliga | C72: 2025/2026 | D72: 45963 | E72: 0.66666667 | F72: SK Rapid | G72: Sturm Graz | H72: 2 | I72: 1 | J72: H | N72: 26 | O72: 36 | P72: 265 | Q72: 25 | R72: 342 | S72: 255 | T72: 2.72 | U72: 3.6 | V72: 2.76 | W72: 2.55 | X72: 3.5 | Y72: 2.5
A73: Austria | B73: Bundesliga | C73: 2025/2026 | D73: 45969 | E73: 0.66666667 | F73: Austria Vienna | G73: Grazer AK | H73: 2 | I73: 1 | J73: H | N73: 175 | O73: 36 | P73: 55 | Q73: 17 | R73: 343 | S73: 494 | T73: 1.74 | U73: 3.75 | V73: 5.8 | W73: 1.66 | X73: 3.5 | Y73: 5.5
A74: Austria | B74: Bundesliga | C74: 2025/2026 | D74: 45969 | E74: 0.66666667 | F74: Ried | G74: BW Linz | H74: 2 | I74: 1 | J74: H | N74: 215 | O74: 33 | P74: 36 | Q74: 207 | R74: 32 | S74: 347 | T74: 2.24 | U74: 3.3 | V74: 3.65 | W74: 2.1 | X74: 3.25 | Y74: 3.5
A75: Austria | B75: Bundesliga | C75: 2025/2026 | D75: 45969 | E75: 0.66666667 | F75: Wolfsberger AC | G75: Hartberg | H75: 1 | I75: 2 | J75: A | N75: 191 | O75: 36 | P75: 42 | Q75: 184 | R75: 347 | S75: 396 | T75: 1.94 | U75: 3.75 | V75: 4.4 | W75: 1.81 | X75: 3.5 | Y75: 4.2
A76: Austria | B76: Bundesliga | C76: 2025/2026 | D76: 45970 | E76: 0.5625 | F76: LASK | G76: Altach | H76: 1 | I76: 0 | J76: H | N76: 187 | O76: 35 | P76: 475 | Q76: 182 | R76: 336 | S76: 419 | T76: 1.88 | U76: 3.55 | V76: 4.9 | W76: 1.81 | X76: 3.5 | Y76: 4.1
A77: Austria | B77: Bundesliga | C77: 2025/2026 | D77: 45970 | E77: 0.5625 | F77: Tirol | G77: SK Rapid | H77: 1 | I77: 1 | J77: D | N77: 36 | O77: 35 | P77: 223 | Q77: 331 | R77: 333 | S77: 208 | T77: 3.7 | U77: 3.5 | V77: 2.18 | W77: 3.4 | X77: 3.4 | Y77: 2.05
A78: Austria | B78: Bundesliga | C78: 2025/2026 | D78: 45970 | E78: 0.66666667 | F78: Sturm Graz | G78: Salzburg | H78: 1 | I78: 1 | J78: D | N78: 238 | O78: 36 | P78: 29 | Q78: 23 | R78: 349 | S78: 277 | T78: 2.5 | U78: 3.6 | V78: 3 | W78: 2.3 | X78: 3.6 | Y78: 2.75
... A157: Austria | B157: Bundesliga | C157: 2025/2026 | D157: 46124 | E157: 0.66666667 | F157: Austria Vienna | G157: SK Rapid | H157: 1 | I157: 1 | J157: D | N157: 275 | O157: 32 | P157: 288 | Q157: 26 | R157: 302 | S157: 272 | T157: 2.9 | U157: 3.05 | V157: 2.94 | W157: 2.65 | X157: 3.1 | Y157: 2.65
A158: Austria | B158: Bundesliga | C158: 2025/2026 | D158: 46129 | E158: 0.77083333 | F158: Grazer AK | G158: Ried | H158: 1 | I158: 1 | J158: D | N158: 26 | O158: 315 | P158: 31 | Q158: 249 | R158: 298 | S158: 284 | W158: 2.55 | X158: 2.85 | Y158: 2.85
...

Sheet Mannschaften
A1: Mannschaften | B1: Abgleich | C1: Heimtore | D1: Auswärtstore | E1: Gesamttore | F1: Anzahl der Siege | G1: meistegeschossene Tore pro Spiel
A2: Sturm Graz | B2: =COUNTIF(A:A,A2) -> 1 | C2: =SUMIF('AT2526'!F:F,Mannschaften!A2,'AT2526'!H:H) -> 17 | D2: =SUMIF('AT2526'!G:G,Mannschaften!A2,'AT2526'!I:I) -> 34 | E2: =C2+D2 -> 51 | F2: =COUNTIF(Spiele!E:E,Mannschaften!A2) -> 16 | G2: =_xlfn.XLOOKUP(A2,meistegeschosseneToreproSpiel!A:A,meistegeschosseneToreproSpiel!B:B) -> 5
A3: Hartberg | B3: =COUNTIF(A:A,A3) -> 1 | C3: =SUMIF('AT2526'!F:F,Mannschaften!A3,'AT2526'!H:H) -> 19 | D3: =SUMIF('AT2526'!G:G,Mannschaften!A3,'AT2526'!I:I) -> 21 | E3: =C3+D3 -> 40 | F3: =COUNTIF(Spiele!E:E,Mannschaften!A3) -> 10 | G3: =_xlfn.XLOOKUP(A3,meistegeschosseneToreproSpiel!A:A,meistegeschosseneToreproSpiel!B:B) -> 3
A4: Altach | B4: =COUNTIF(A:A,A4) -> 1 | C4: =SUMIF('AT2526'!F:F,Mannschaften!A4,'AT2526'!H:H) -> 21 | D4: =SUMIF('AT2526'!G:G,Mannschaften!A4,'AT2526'!I:I) -> 15 | E4: =C4+D4 -> 36 | F4: =COUNTIF(Spiele!E:E,Mannschaften!A4) -> 10 | G4: =_xlfn.XLOOKUP(A4,meistegeschosseneToreproSpiel!A:A,meistegeschosseneToreproSpiel!B:B) -> 3
A5: Salzburg | B5: =COUNTIF(A:A,A5) -> 1 | C5: =SUMIF('AT2526'!F:F,Mannschaften!A5,'AT2526'!H:H) -> 29 | D5: =SUMIF('AT2526'!G:G,Mannschaften!A5,'AT2526'!I:I) -> 27 | E5: =C5+D5 -> 56 | F5: =COUNTIF(Spiele!E:E,Mannschaften!A5) -> 13 | G5: =_xlfn.XLOOKUP(A5,meistegeschosseneToreproSpiel!A:A,meistegeschosseneToreproSpiel!B:B) -> 5
A6: Austria Vienna | B6: =COUNTIF(A:A,A6) -> 1 | C6: =SUMIF('AT2526'!F:F,Mannschaften!A6,'AT2526'!H:H) -> 19 | D6: =SUMIF('AT2526'!G:G,Mannschaften!A6,'AT2526'!I:I) -> 26 | E6: =C6+D6 -> 45 | F6: =COUNTIF(Spiele!E:E,Mannschaften!A6) -> 14 | G6: =_xlfn.XLOOKUP(A6,meistegeschosseneToreproSpiel!A:A,meistegeschosseneToreproSpiel!B:B) -> 3
A7: BW Linz | B7: =COUNTIF(A:A,A7) -> 1 | C7: =SUMIF('AT2526'!F:F,Mannschaften!A7,'AT2526'!H:H) -> 28 | D7: =SUMIF('AT2526'!G:G,Mannschaften!A7,'AT2526'!I:I) -> 9 | E7: =C7+D7 -> 37 | F7: =COUNTIF(Spiele!E:E,Mannschaften!A7) -> 8 | G7: =_xlfn.XLOOKUP(A7,meistegeschosseneToreproSpiel!A:A,meistegeschosseneToreproSpiel!B:B) -> 5
A8: Ried | B8: =COUNTIF(A:A,A8) -> 1 | C8: =SUMIF('AT2526'!F:F,Mannschaften!A8,'AT2526'!H:H) -> 21 | D8: =SUMIF('AT2526'!G:G,Mannschaften!A8,'AT2526'!I:I) -> 17 | E8: =C8+D8 -> 38 | F8: =COUNTIF(Spiele!E:E,Mannschaften!A8) -> 12 | G8: =_xlfn.XLOOKUP(A8,meistegeschosseneToreproSpiel!A:A,meistegeschosseneToreproSpiel!B:B) -> 3
A9: Grazer AK | B9: =COUNTIF(A:A,A9) -> 1 | C9: =SUMIF('AT2526'!F:F,Mannschaften!A9,'AT2526'!H:H) -> 26 | D9: =SUMIF('AT2526'!G:G,Mannschaften!A9,'AT2526'!I:I) -> 16 | E9: =C9+D9 -> 42 | F9: =COUNTIF(Spiele!E:E,Mannschaften!A9) -> 9 | G9: =_xlfn.XLOOKUP(A9,meistegeschosseneToreproSpiel!A:A,meistegeschosseneToreproSpiel!B:B) -> 5
A10: Wolfsberger AC | B10: =COUNTIF(A:A,A10) -> 1 | C10: =SUMIF('AT2526'!F:F,Mannschaften!A10,'AT2526'!H:H) -> 20 | D10: =SUMIF('AT2526'!G:G,Mannschaften!A10,'AT2526'!I:I) -> 21 | E10: =C10+D10 -> 41 | F10: =COUNTIF(Spiele!E:E,Mannschaften!A10) -> 11 | G10: =_xlfn.XLOOKUP(A10,meistegeschosseneToreproSpiel!A:A,meistegeschosseneToreproSpiel!B:B) -> 4
A11: SK Rapid | B11: =COUNTIF(A:A,A11) -> 1 | C11: =SUMIF('AT2526'!F:F,Mannschaften!A11,'AT2526'!H:H) -> 19 | D11: =SUMIF('AT2526'!G:G,Mannschaften!A11,'AT2526'!I:I) -> 17 | E11: =C11+D11 -> 36 | F11: =COUNTIF(Spiele!E:E,Mannschaften!A11) -> 12 | G11: =_xlfn.XLOOKUP(A11,meistegeschosseneToreproSpiel!A:A,meistegeschosseneToreproSpiel!B:B) -> 4
A12: LASK | B12: =COUNTIF(A:A,A12) -> 1 | C12: =SUMIF('AT2526'!F:F,Mannschaften!A12,'AT2526'!H:H) -> 28 | D12: =SUMIF('AT2526'!G:G,Mannschaften!A12,'AT2526'!I:I) -> 28 | E12: =C12+D12 -> 56 | F12: =COUNTIF(Spiele!E:E,Mannschaften!A12) -> 17 | G12: =_xlfn.XLOOKUP(A12,meistegeschosseneToreproSpiel!A:A,meistegeschosseneToreproSpiel!B:B) -> 5
A13: Tirol | B13: =COUNTIF(A:A,A13) -> 1 | C13: =SUMIF('AT2526'!F:F,Mannschaften!A13,'AT2526'!H:H) -> 26 | D13: =SUMIF('AT2526'!G:G,Mannschaften!A13,'AT2526'!I:I) -> 14 | E13: =C13+D13 -> 40 | F13: =COUNTIF(Spiele!E:E,Mannschaften!A13) -> 10 | G13: =_xlfn.XLOOKUP(A13,meistegeschosseneToreproSpiel!A:A,meistegeschosseneToreproSpiel!B:B) -> 4

Sheet Spiele
A1: Home | B1: Away | C1: HG | D1: AG | E1: Winner | F1: Punkte H | G1: Punkte A
A2: LASK | B2: Sturm Graz | C2: 0 | D2: 2 | E2: {=_xlfn.IFS(C2=D2, ,C2>D2,A2,D2>C2,B2)} -> Sturm Graz | F2: {=_xlfn.IFS(E2=0,1,E2=A2,3,E2<>A2,0)} -> 0 | G2: {=_xlfn.IFS(E2=0,1,E2=B2,3,E2<>B2,0)} -> 3
A3: Tirol | B3: Hartberg | C3: 4 | D3: 2 | E3: {=_xlfn.IFS(C3=D3, ,C3>D3,A3,D3>C3,B3)} -> Tirol | F3: {=_xlfn.IFS(E3=0,1,E3=A3,3,E3<>A3,0)} -> 3 | G3: {=_xlfn.IFS(E3=0,1,E3=B3,3,E3<>B3,0)} -> 0
A4: Wolfsberger AC | B4: Altach | C4: 0 | D4: 2 | E4: {=_xlfn.IFS(C4=D4, ,C4>D4,A4,D4>C4,B4)} -> Altach | F4: {=_xlfn.IFS(E4=0,1,E4=A4,3,E4<>A4,0)} -> 0 | G4: {=_xlfn.IFS(E4=0,1,E4=B4,3,E4<>B4,0)} -> 3
A5: Ried | B5: Salzburg | C5: 2 | D5: 2 | E5: {=_xlfn.IFS(C5=D5, ,C5>D5,A5,D5>C5,B5)} -> 0 | F5: {=_xlfn.IFS(E5=0,1,E5=A5,3,E5<>A5,0)} -> 1 | G5: {=_xlfn.IFS(E5=0,1,E5=B5,3,E5<>B5,0)} -> 1
A6: Grazer AK | B6: Austria Vienna | C6: 2 | D6: 2 | E6: {=_xlfn.IFS(C6=D6, ,C6>D6,A6,D6>C6,B6)} -> 0 | F6: {=_xlfn.IFS(E6=0,1,E6=A6,3,E6<>A6,0)} -> 1 | G6: {=_xlfn.IFS(E6=0,1,E6=B6,3,E6<>B6,0)} -> 1
A7: SK Rapid | B7: BW Linz | C7: 1 | D7: 0 | E7: {=_xlfn.IFS(C7=D7, ,C7>D7,A7,D7>C7,B7)} -> SK Rapid | F7: {=_xlfn.IFS(E7=0,1,E7=A7,3,E7<>A7,0)} -> 3 | G7: {=_xlfn.IFS(E7=0,1,E7=B7,3,E7<>B7,0)} -> 0
A8: Altach | B8: Ried | C8: 1 | D8: 0 | E8: {=_xlfn.IFS(C8=D8, ,C8>D8,A8,D8>C8,B8)} -> Altach | F8: {=_xlfn.IFS(E8=0,1,E8=A8,3,E8<>A8,0)} -> 3 | G8: {=_xlfn.IFS(E8=0,1,E8=B8,3,E8<>B8,0)} -> 0
A9: BW Linz | B9: Hartberg | C9: 0 | D9: 1 | E9: {=_xlfn.IFS(C9=D9, ,C9>D9,A9,D9>C9,B9)} -> Hartberg | F9: {=_xlfn.IFS(E9=0,1,E9=A9,3,E9<>A9,0)} -> 0 | G9: {=_xlfn.IFS(E9=0,1,E9=B9,3,E9<>B9,0)} -> 3
A10: Salzburg | B10: Grazer AK | C10: 5 | D10: 0 | E10: {=_xlfn.IFS(C10=D10, ,C10>D10,A10,D10>C10,B10)} -> Salzburg | F10: {=_xlfn.IFS(E10=0,1,E10=A10,3,E10<>A10,0)} -> 3 | G10: {=_xlfn.IFS(E10=0,1,E10=B10,3,E10<>B10,0)} -> 0
A11: Austria Vienna | B11: Wolfsberger AC | C11: 0 | D11: 2 | E11: {=_xlfn.IFS(C11=D11, ,C11>D11,A11,D11>C11,B11)} -> Wolfsberger AC | F11: {=_xlfn.IFS(E11=0,1,E11=A11,3,E11<>A11,0)} -> 0 | G11: {=_xlfn.IFS(E11=0,1,E11=B11,3,E11<>B11,0)} -> 3
A12: Sturm Graz | B12: SK Rapid | C12: 1 | D12: 2 | E12: {=_xlfn.IFS(C12=D12, ,C12>D12,A12,D12>C12,B12)} -> SK Rapid | F12: {=_xlfn.IFS(E12=0,1,E12=A12,3,E12<>A12,0)} -> 0 | G12: {=_xlfn.IFS(E12=0,1,E12=B12,3,E12<>B12,0)} -> 3
A13: Tirol | B13: LASK | C13: 3 | D13: 1 | E13: {=_xlfn.IFS(C13=D13, ,C13>D13,A13,D13>C13,B13)} -> Tirol | F13: {=_xlfn.IFS(E13=0,1,E13=A13,3,E13<>A13,0)} -> 3 | G13: {=_xlfn.IFS(E13=0,1,E13=B13,3,E13<>B13,0)} -> 0
... A193: Sturm Graz | B193: SK Rapid | C193: 2 | D193: 0 | E193: {=_xlfn.IFS(C193=D193, ,C193>D193,A193,D193>C193,B193)} -> Sturm Graz | F193: {=_xlfn.IFS(E193=0,1,E193=A193,3,E193<>A193,0)} -> 3 | G193: {=_xlfn.IFS(E193=0,1,E193=B193,3,E193<>B193,0)} -> 0

Sheet meistegeschosseneToreproSpiel
A1: Mannschaften | B1: meiste geschossene Tore pro Spiel
A2: Sturm Graz | B2: =MAX(_xlfn.MAXIFS(Spiele!C:C,Spiele!A:A,A2),_xlfn.MAXIFS(Spiele!D:D,Spiele!B:B,A2)) -> 5
A3: Hartberg | B3: =MAX(_xlfn.MAXIFS(Spiele!C:C,Spiele!A:A,A3),_xlfn.MAXIFS(Spiele!D:D,Spiele!B:B,A3)) -> 3
A4: Altach | B4: =MAX(_xlfn.MAXIFS(Spiele!C:C,Spiele!A:A,A4),_xlfn.MAXIFS(Spiele!D:D,Spiele!B:B,A4)) -> 3
A5: Salzburg | B5: =MAX(_xlfn.MAXIFS(Spiele!C:C,Spiele!A:A,A5),_xlfn.MAXIFS(Spiele!D:D,Spiele!B:B,A5)) -> 5
A6: Austria Vienna | B6: =MAX(_xlfn.MAXIFS(Spiele!C:C,Spiele!A:A,A6),_xlfn.MAXIFS(Spiele!D:D,Spiele!B:B,A6)) -> 3
A7: BW Linz | B7: =MAX(_xlfn.MAXIFS(Spiele!C:C,Spiele!A:A,A7),_xlfn.MAXIFS(Spiele!D:D,Spiele!B:B,A7)) -> 5
A8: Ried | B8: =MAX(_xlfn.MAXIFS(Spiele!C:C,Spiele!A:A,A8),_xlfn.MAXIFS(Spiele!D:D,Spiele!B:B,A8)) -> 3
A9: Grazer AK | B9: =MAX(_xlfn.MAXIFS(Spiele!C:C,Spiele!A:A,A9),_xlfn.MAXIFS(Spiele!D:D,Spiele!B:B,A9)) -> 5
A10: Wolfsberger AC | B10: =MAX(_xlfn.MAXIFS(Spiele!C:C,Spiele!A:A,A10),_xlfn.MAXIFS(Spiele!D:D,Spiele!B:B,A10)) -> 4
A11: SK Rapid | B11: =MAX(_xlfn.MAXIFS(Spiele!C:C,Spiele!A:A,A11),_xlfn.MAXIFS(Spiele!D:D,Spiele!B:B,A11)) -> 4
A12: LASK | B12: =MAX(_xlfn.MAXIFS(Spiele!C:C,Spiele!A:A,A12),_xlfn.MAXIFS(Spiele!D:D,Spiele!B:B,A12)) -> 5
A13: Tirol | B13: =MAX(_xlfn.MAXIFS(Spiele!C:C,Spiele!A:A,A13),_xlfn.MAXIFS(Spiele!D:D,Spiele!B:B,A13)) -> 4

Sheet Tore nach Kalendertag
A3: Zeilenbeschriftungen | B3: Summe von HG | C3: Summe von AG | D3: Summe von Summe Tore
A4: 45870 | B4: 0 | C4: 2 | D4: 2
A5: 45871 | B5: 6 | C5: 6 | D5: 12
A6: 45872 | B6: 3 | C6: 2 | D6: 5
A7: 45878 | B7: 6 | C7: 1 | D7: 7
A8: 45879 | B8: 4 | C8: 5 | D8: 9
A9: 45885 | B9: 3 | C9: 6 | D9: 9
A10: 45886 | B10: 5 | C10: 1 | D10: 6
A11: 45892 | B11: 3 | C11: 2 | D11: 5
A12: 45893 | B12: 3 | C12: 6 | D12: 9
A13: 45899 | B13: 3 | C13: 8 | D13: 11
A14: 45900 | B14: 2 | C14: 2 | D14: 4
A15: 45913 | B15: 7 | C15: 1 | D15: 8
... A75: 46159 | B75: 3 | C75: 6 | D75: 9
A76: (Leer) | D76: 0
A77: Gesamtergebnis | B77: 273 | C77: 245 | D77: 518

Sheet Pivot Homepoints
A3: Homepoints von | B3: Gegner
A4: Mannschaften | B4: Altach | C4: Austria Vienna | D4: BW Linz | E4: Grazer AK | F4: Hartberg | G4: LASK | H4: Ried | I4: Salzburg | J4: SK Rapid | K4: Sturm Graz | L4: Tirol | M4: Wolfsberger AC | N4: Gesamtergebnis
A5: Altach | C5: 3 | D5: 6 | E5: 4 | F5: 1 | G5: 3 | H5: 6 | I5: 1 | J5: 1 | K5: 0 | L5: 2 | M5: 3 | N5: 30
A6: Austria Vienna | B6: 3 | D6: 0 | E6: 3 | F6: 3 | G6: 1 | H6: 3 | I6: 0 | J6: 4 | K6: 3 | L6: 1 | M6: 0 | N6: 21
A7: BW Linz | B7: 6 | C7: 0 | E7: 3 | F7: 0 | G7: 0 | H7: 3 | I7: 0 | J7: 1 | K7: 0 | L7: 3 | M7: 6 | N7: 22
A8: Grazer AK | B8: 4 | C8: 1 | D8: 6 | F8: 1 | G8: 0 | H8: 4 | I8: 1 | J8: 1 | K8: 0 | L8: 4 | M8: 3 | N8: 25
A9: LASK | B9: 3 | C9: 6 | D9: 3 | E9: 3 | F9: 2 | H9: 0 | I9: 3 | J9: 6 | K9: 1 | L9: 3 | M9: 3 | N9: 33
A10: Ried | B10: 6 | C10: 0 | D10: 6 | E10: 4 | F10: 0 | G10: 1 | I10: 1 | J10: 0 | K10: 0 | L10: 6 | M10: 3 | N10: 27
A11: Salzburg | B11: 1 | C11: 3 | D11: 1 | E11: 3 | F11: 1 | G11: 3 | H11: 3 | J11: 3 | K11: 1 | L11: 0 | M11: 3 | N11: 22
A12: Hartberg | B12: 1 | C12: 3 | D12: 1 | E12: 3 | G12: 1 | H12: 3 | I12: 0 | J12: 1 | K12: 0 | L12: 3 | M12: 1 | N12: 17
A13: SK Rapid | B13: 1 | C13: 0 | D13: 3 | E13: 0 | F13: 1 | G13: 3 | H13: 0 | I13: 6 | K13: 3 | L13: 3 | M13: 3 | N13: 23
A14: Sturm Graz | B14: 3 | C14: 1 | D14: 3 | E14: 3 | F14: 4 | G14: 1 | H14: 3 | I14: 2 | J14: 3 | L14: 0 | M14: 0 | N14: 23
A15: Tirol | B15: 1 | C15: 0 | D15: 4 | E15: 3 | F15: 3 | G15: 3 | H15: 4 | I15: 0 | J15: 1 | K15: 3 | M15: 4 | N15: 26
A16: Wolfsberger AC | B16: 1 | C16: 3 | D16: 4 | E16: 4 | F16: 0 | G16: 3 | H16: 1 | I16: 3 | J16: 0 | K16: 1 | L16: 4 | N16: 24
A17: Gesamtergebnis | B17: 30 | C17: 20 | D17: 37 | E17: 33 | F17: 16 | G17: 19 | H17: 30 | I17: 17 | J17: 21 | K17: 12 | L17: 29 | M17: 29 | N17: 293

Sheet Pivot Awaypoints
A3: Awaypoints von | B3: Gegner
A4: Mannschaften | B4: Altach | C4: Austria Vienna | D4: BW Linz | E4: Grazer AK | F4: Hartberg | G4: LASK | H4: Ried | I4: Salzburg | J4: SK Rapid | K4: Sturm Graz | L4: Tirol | M4: Wolfsberger AC | N4: Gesamtergebnis
A5: Altach | C5: 0 | D5: 0 | E5: 1 | F5: 1 | G5: 0 | H5: 0 | I5: 1 | J5: 1 | K5: 0 | L5: 4 | M5: 4 | N5: 12
A6: Austria Vienna | B6: 0 | D6: 3 | E6: 1 | F6: 3 | G6: 0 | H6: 3 | I6: 3 | J6: 6 | K6: 4 | L6: 3 | M6: 0 | N6: 26
A7: BW Linz | B7: 0 | C7: 3 | E7: 0 | F7: 1 | G7: 0 | H7: 0 | I7: 1 | J7: 0 | K7: 0 | L7: 1 | M7: 1 | N7: 7
A8: Grazer AK | B8: 1 | C8: 0 | D8: 3 | F8: 0 | G8: 0 | H8: 1 | I8: 0 | J8: 3 | K8: 0 | L8: 3 | M8: 1 | N8: 12
A9: Hartberg | B9: 1 | C9: 3 | D9: 3 | E9: 1 | G9: 2 | H9: 3 | I9: 4 | J9: 4 | K9: 1 | L9: 0 | M9: 3 | N9: 25
A10: LASK | B10: 0 | C10: 4 | D10: 3 | E10: 3 | F10: 4 | H10: 1 | I10: 3 | J10: 3 | K10: 4 | L10: 0 | M10: 0 | N10: 25
A11: Ried | B11: 0 | C11: 0 | D11: 3 | E11: 1 | F11: 0 | G11: 3 | I11: 0 | J11: 3 | K11: 0 | L11: 1 | M11: 4 | N11: 15
A12: Salzburg | B12: 1 | C12: 6 | D12: 3 | E12: 1 | F12: 6 | G12: 3 | H12: 1 | J12: 0 | K12: 2 | L12: 3 | M12: 0 | N12: 26
A13: SK Rapid | B13: 1 | C13: 1 | D13: 1 | E13: 1 | F13: 4 | G13: 0 | H13: 3 | I13: 3 | K13: 3 | L13: 1 | M13: 3 | N13: 21
A14: Sturm Graz | B14: 3 | C14: 3 | D14: 3 | E14: 3 | F14: 6 | G14: 4 | H14: 3 | I14: 4 | J14: 3 | L14: 0 | M14: 1 | N14: 33
A15: Tirol | B15: 2 | C15: 1 | D15: 3 | E15: 1 | F15: 0 | G15: 0 | H15: 0 | I15: 3 | J15: 0 | K15: 3 | M15: 1 | N15: 14
A16: Wolfsberger AC | B16: 3 | C16: 3 | D16: 0 | E16: 3 | F16: 1 | G16: 0 | H16: 3 | I16: 0 | J16: 0 | K16: 3 | L16: 1 | N16: 17
A17: Gesamtergebnis | B17: 12 | C17: 24 | D17: 25 | E17: 16 | F17: 26 | G17: 12 | H17: 18 | I17: 22 | J17: 23 | K17: 20 | L17: 17 | M17: 18 | N17: 233
